src/test/resources/BTCZAR_tradehistory.json
[
  {
    "price": "1876795",
    "quantity": "0.0001",
    "currencyPair": "BTCZAR",
    "tradedAt": "2025-10-18T21:25:27.739Z",
    "takerSide": "buy",
    "sequenceId": 1.370000000002671e+18,
    "id": "0199f936-943b-7326-9c3a-2b502d767326",
    "quoteVolume": "578.05286"
  },
  {
    "price": "1876678",
    "quantity": "0.00001",
    "currencyPair": "BTCZAR",
    "tradedAt": "2025-10-18T21:25:27.739Z",
    "takerSide": "buy",
    "sequenceId": 1.370000000002671e+18,
    "id": "0199f936-943b-7c9a-aadc-830614f33c9a",
    "quoteVolume": "18.76678"
  },
  {
    "price": "1874456",
    "quantity": "0.00002437",
    "currencyPair": "BTCZAR",
    "tradedAt": "2025-10-18T21:21:23.067Z",
    "takerSide": "sell",
    "sequenceId": 1.370000000002671e+18,
    "id": "0199f932-d87b-7b13-92ae-522246d19b13",
    "quoteVolume": "45.68049272"
  },
  {
    "price": "1873870",
    "quantity": "0.00053365",
    "currencyPair": "BTCZAR",
    "tradedAt": "2025-10-18T21:16:36.944Z",
    "takerSide": "buy",
    "sequenceId": 1.370000000002671e+18,
    "id": "0199f92e-7ad0-7fd1-9e41-37e7d44f5fd1",
    "quoteVolume": "999.9907255"
  },
  {
    "price": "1874248",
    "quantity": "0.00004816",
    "currencyPair": "BTCZAR",
    "tradedAt": "2025-10-18T21:14:25.441Z",
    "takerSide": "buy",
    "sequenceId": 1.370000000002671e+18,
    "id": "0199f92c-7921-7f6c-9f5b-d12cc03f5f6c",
    "quoteVolume": "90.26378368"
  },
  {
    "price": "1873861",
    "quantity": "0.00002709",
    "currencyPair": "BTCZAR",
    "tradedAt": "2025-10-18T21:11:49.383Z",
    "takerSide": "sell",
    "sequenceId": 1.370000000002671e+18,
    "id": "0199f92a-1787-7d81-a036-5b65611d2d81",
    "quoteVolume": "50.76289449"
  },
  {
    "price": "1873628",
    "quantity": "0.00002051",
    "currencyPair": "BTCZAR",
    "tradedAt": "2025-10-18T21:11:10.976Z",
    "takerSide": "buy",
    "sequenceId": 1.370000000002671e+18,
    "id": "0199f929-8180-7415-a095-d3a48beff415",
    "quoteVolume": "38.42811028"
  },
  {
    "price": "1874999",
    "quantity": "0.00026665",
    "currencyPair": "BTCZAR",
    "tradedAt": "2025-10-18T21:08:58.214Z",
    "takerSide": "sell",
    "sequenceId": 1.370000000002671e+18,
    "id": "0199f927-7ae6-7670-a4a8-e2c8b4017670",
    "quoteVolume": "499.96848335"
  },
  {
    "price": "1875483",
    "quantity": "0.00014188",
    "currencyPair": "BTCZAR",
    "tradedAt": "2025-10-18T21:01:28.469Z",
    "takerSide": "sell",
    "sequenceId": 1.370000000002671e+18,
    "id": "0199f920-9e15-7b6c-92b0-17754c73bb6c",
    "quoteVolume": "266.09352804"
  },
  {
    "price": "1877642",
    "quantity": "0.00005325",
    "currencyPair": "BTCZAR",
    "tradedAt": "2025-10-18T20:56:37.646Z",
    "takerSide": "buy",
    "sequenceId": 1.370000000002671e+18,
    "id": "0199f91c-2e0e-7525-9186-42569627c525",
    "quoteVolume": "99.9844365"
  },
  {
    "price": "1876740",
    "quantity": "0.00007579",
    "currencyPair": "BTCZAR",
    "tradedAt": "2025-10-18T20:53:56.908Z",
    "takerSide": "sell",
    "sequenceId": 1.370000000002671e+18,
    "id": "0199f919-ba2c-7970-8b8b-ea9df50b2970",
    "quoteVolume": "142.2381246"
  },
  {
    "price": "1877103",
    "quantity": "0.00045815",
    "currencyPair": "BTCZAR",
    "tradedAt": "2025-10-18T20:52:25.199Z",
    "takerSide": "buy",
    "sequenceId": 1.370000000002671e+18,
    "id": "0199f918-53ef-7550-8458-798b33fdb550",
    "quoteVolume": "859.99473945"
  },
  {
    "price": "1878716",
    "quantity": "0.06943788",
    "currencyPair": "BTCZAR",
    "tradedAt": "2025-10-18T20:52:14.391Z",
    "takerSide": "sell",
    "sequenceId": 1.370000000002671e+18,
    "id": "0199f918-29b7-7f18-b8f9-de58f1452f18",
    "quoteVolume": "130454.05616208"
  },
  {
    "price": "1878717",
    "quantity": "0.00012468",
    "currencyPair": "BTCZAR",
    "tradedAt": "2025-10-18T20:52:08.579Z",
    "takerSide": "buy",
    "sequenceId": 1.370000000002671e+18,
    "id": "0199f918-1303-7d40-9b4c-c900684ded40",
    "quoteVolume": "234.23843556"
  },
  {
    "price": "1879044",
    "quantity": "0.0001",
    "currencyPair": "BTCZAR",
    "tradedAt": "2025-10-18T20:38:41.739Z",
    "takerSide": "sell",
    "sequenceId": 1.370000000002671e+18,
    "id": "0199f90b-c34b-7fe9-a497-9d01850f7fe9",
    "quoteVolume": "187.9044"
  },
  {
    "price": "1879028",
    "quantity": "0.00004824",
    "currencyPair": "BTCZAR",
    "tradedAt": "2025-10-18T20:38:34.936Z",
    "takerSide": "sell",
    "sequenceId": 1.370000000002671e+18,
    "id": "0199f90b-a8b8-7032-8876-bb8eff2b8032",
    "quoteVolume": "90.64431072"
  },
  {
    "price": "1879739",
    "quantity": "0.00000286",
    "currencyPair": "BTCZAR",
    "tradedAt": "2025-10-18T20:38:01.893Z",
    "takerSide": "buy",
    "sequenceId": 1.370000000002671e+18,
    "id": "0199f90b-27a5-733d-b4ba-53cda7aab33d",
    "quoteVolume": "5.37605354"
  },
  {
    "price": "1879738",
    "quantity": "0.00001",
    "currencyPair": "BTCZAR",
    "tradedAt": "2025-10-18T20:38:01.893Z",
    "takerSide": "buy",
    "sequenceId": 1.370000000002671e+18,
    "id": "0199f90b-27a5-7649-974b-3dade52c0649",
    "quoteVolume": "18.79738"
  },
  {
    "price": "1878667",
    "quantity": "0.01183134",
    "currencyPair": "BTCZAR",
    "tradedAt": "2025-10-18T20:37:01.026Z",
    "takerSide": "sell",
    "sequenceId": 1.370000000002671e+18,
    "id": "0199f90a-39e2-7fd7-94fa-3d993f8b2fd7",
    "quoteVolume": "22227.14802378"
  },
  {
    "price": "1878756",
    "quantity": "0.00002002",
    "currencyPair": "BTCZAR",
    "tradedAt": "2025-10-18T20:37:01.026Z",
    "takerSide": "sell",
    "sequenceId": 1.370000000002671e+18,
    "id": "0199f90a-39e2-7ebd-89c3-2d008e33cebd",
    "quoteVolume": "37.61269512"
  },
  {
    "price": "1878757",
    "quantity": "0.00012761",
    "currencyPair": "BTCZAR",
    "tradedAt": "2025-10-18T20:37:01.026Z",
    "takerSide": "sell",
    "sequenceId": 1.370000000002671e+18,
    "id": "0199f90a-39e2-7137-a1c2-362921fde137",
    "quoteVolume": "239.74818077"
  },
  {
    "price": "1879507",
    "quantity": "0.00000994",
    "currencyPair": "BTCZAR",
    "tradedAt": "2025-10-18T20:33:49.629Z",
    "takerSide": "sell",
    "sequenceId": 1.370000000002671e+18,
    "id": "0199f907-4e3d-75bc-a3b8-0ab5e28ae5bc",
    "quoteVolume": "18.68229958"
  },
  {
    "price": "1879572",
    "quantity": "0.00087337",
    "currencyPair": "BTCZAR",
    "tradedAt": "2025-10-18T20:29:12.446Z",
    "takerSide": "buy",
    "sequenceId": 1.370000000002671e+18,
    "id": "0199f903-137e-75c8-ba5a-8dc909e535c8",
    "quoteVolume": "1641.56179764"
  },
  {
    "price": "1879571",
    "quantity": "0.0001",
    "currencyPair": "BTCZAR",
    "tradedAt": "2025-10-18T20:29:12.446Z",
    "takerSide": "buy",
    "sequenceId": 1.370000000002671e+18,
    "id": "0199f903-137e-775b-a0b5-b42f42a7775b",
    "quoteVolume": "187.9571"
  },
  {
    "price": "1879351",
    "quantity": "0.0010908",
    "currencyPair": "BTCZAR",
    "tradedAt": "2025-10-18T20:27:19.351Z",
    "takerSide": "buy",
    "sequenceId": 1.370000000002671e+18,
    "id": "0199f901-59b7-7285-a44d-ff5232906285",
    "quoteVolume": "2049.9960708"
  },
  {
    "price": "1879361",
    "quantity": "0.00001225",
    "currencyPair": "BTCZAR",
    "tradedAt": "2025-10-18T20:26:49.529Z",
    "takerSide": "buy",
    "sequenceId": 1.370000000002671e+18,
    "id": "0199f900-e539-74f6-b604-4ec12c91b4f6",
    "quoteVolume": "23.02217225"
  },
  {
    "price": "1879357",
    "quantity": "0.00001",
    "currencyPair": "BTCZAR",
    "tradedAt": "2025-10-18T20:26:49.529Z",
    "takerSide": "buy",
    "sequenceId": 1.370000000002671e+18,
    "id": "0199f900-e539-7564-aee7-24e68b162564",
    "quoteVolume": "18.79357"
  },
  {
    "price": "1879583",
    "quantity": "0.017787",
    "currencyPair": "BTCZAR",
    "tradedAt": "2025-10-18T20:26:07.175Z",
    "takerSide": "buy",
    "sequenceId": 1.370000000002671e+18,
    "id": "0199f900-3fc7-799d-a42f-e5dacf08399d",
    "quoteVolume": "33432.142821"
  },
  {
    "price": "1878404",
    "quantity": "0.00002243",
